Traceback (most recent call last):
  File "C:\Users\MyBook Z Series\AppData\Local\Packages\PythonSoftwareFoundation.Python.3.13_qbz5n2kfra8p0\LocalCache\local-packages\Python313\site-packages\jupyter_cache\executors\utils.py", line 58, in single_nb_execution
    executenb(
    ~~~~~~~~~^
        nb,
        ^^^
    ...<4 lines>...
        **kwargs,
        ^^^^^^^^^
    )
    ^
  File "C:\Users\MyBook Z Series\AppData\Local\Packages\PythonSoftwareFoundation.Python.3.13_qbz5n2kfra8p0\LocalCache\local-packages\Python313\site-packages\nbclient\client.py", line 1319, in execute
    return NotebookClient(nb=nb, resources=resources, km=km, **kwargs).execute()
           ~~~~~~~~~~~~~~~~~~~~~~~~~~~~~~~~~~~~~~~~~~~~~~~~~~~~~~~~~~~~~~~~~~~^^
  File "C:\Users\MyBook Z Series\AppData\Local\Packages\PythonSoftwareFoundation.Python.3.13_qbz5n2kfra8p0\LocalCache\local-packages\Python313\site-packages\jupyter_core\utils\__init__.py", line 165, in wrapped
    return loop.run_until_complete(inner)
           ~~~~~~~~~~~~~~~~~~~~~~~^^^^^^^
  File "C:\Program Files\WindowsApps\PythonSoftwareFoundation.Python.3.13_3.13.1008.0_x64__qbz5n2kfra8p0\Lib\asyncio\base_events.py", line 719, in run_until_complete
    return future.result()
           ~~~~~~~~~~~~~^^
  File "C:\Users\MyBook Z Series\AppData\Local\Packages\PythonSoftwareFoundation.Python.3.13_qbz5n2kfra8p0\LocalCache\local-packages\Python313\site-packages\nbclient\client.py", line 709, in async_execute
    await self.async_execute_cell(
        cell, index, execution_count=self.code_cells_executed + 1
    )
  File "C:\Users\MyBook Z Series\AppData\Local\Packages\PythonSoftwareFoundation.Python.3.13_qbz5n2kfra8p0\LocalCache\local-packages\Python313\site-packages\nbclient\client.py", line 1062, in async_execute_cell
    await self._check_raise_for_error(cell, cell_index, exec_reply)
  File "C:\Users\MyBook Z Series\AppData\Local\Packages\PythonSoftwareFoundation.Python.3.13_qbz5n2kfra8p0\LocalCache\local-packages\Python313\site-packages\nbclient\client.py", line 918, in _check_raise_for_error
    raise CellExecutionError.from_cell_and_msg(cell, exec_reply_content)
nbclient.exceptions.CellExecutionError: An error occurred while executing the following cell:
------------------
import numpy as np
from scipy.spatial.distance import euclidean


def compute_distance_between_points(data, point_indices):
    distances = {}
    for (i, j) in point_indices:
        if i != j:
            distances[(i, j)] = euclidean(data[i], data[j])
    return distances


points = np.array([
    [2, 2],
    [3, 5],
    [1, 1],
    [20, 40],
    [5, 3],
    [2,3],
    [4,1],
    [1,5],
    [5,4],
    [3,4]
])

selected_pairs = [(3, 0), (3, 1), (3, 2), (3, 4), (3, 5), (3, 6), (3, 7), (3, 8), (3, 9)]
distances = compute_distance_between_points(points, selected_pairs)

sorted_distances = sorted(distances.items(), key=lambda x: x[1], reverse=True)
print("Jarak Euclidean antara titik yang dipilih (diurutkan dari terbesar ke terkecil):")
for (i, j), dist in sorted_distances:
    print(f"Jarak dari indeks {i} ke indeks {j}: {dist:.2f}")

------------------


[31m---------------------------------------------------------------------------[39m
[31mModuleNotFoundError[39m                       Traceback (most recent call last)
[36mCell[39m[36m [39m[32mIn[1][39m[32m, line 1[39m
[32m----> [39m[32m1[39m [38;5;28;01mimport[39;00m[38;5;250m [39m[34;01mnumpy[39;00m[38;5;250m [39m[38;5;28;01mas[39;00m[38;5;250m [39m[34;01mnp[39;00m
[32m      2[39m [38;5;28;01mfrom[39;00m[38;5;250m [39m[34;01mscipy[39;00m[34;01m.[39;00m[34;01mspatial[39;00m[34;01m.[39;00m[34;01mdistance[39;00m[38;5;250m [39m[38;5;28;01mimport[39;00m euclidean
[32m      5[39m [38;5;28;01mdef[39;00m[38;5;250m [39m[34mcompute_distance_between_points[39m(data, point_indices):

[31mModuleNotFoundError[39m: No module named 'numpy'

