Traceback (most recent call last):
  File "C:\Users\MyBook Z Series\AppData\Local\Packages\PythonSoftwareFoundation.Python.3.11_qbz5n2kfra8p0\LocalCache\local-packages\Python311\site-packages\jupyter_cache\executors\utils.py", line 58, in single_nb_execution
    executenb(
  File "C:\Users\MyBook Z Series\AppData\Local\Packages\PythonSoftwareFoundation.Python.3.11_qbz5n2kfra8p0\LocalCache\local-packages\Python311\site-packages\nbclient\client.py", line 1319, in execute
    return NotebookClient(nb=nb, resources=resources, km=km, **kwargs).execute()
           ^^^^^^^^^^^^^^^^^^^^^^^^^^^^^^^^^^^^^^^^^^^^^^^^^^^^^^^^^^^^^^^^^^^^^
  File "C:\Users\MyBook Z Series\AppData\Local\Packages\PythonSoftwareFoundation.Python.3.11_qbz5n2kfra8p0\LocalCache\local-packages\Python311\site-packages\jupyter_core\utils\__init__.py", line 165, in wrapped
    return loop.run_until_complete(inner)
           ^^^^^^^^^^^^^^^^^^^^^^^^^^^^^^
  File "C:\Program Files\WindowsApps\PythonSoftwareFoundation.Python.3.11_3.11.2544.0_x64__qbz5n2kfra8p0\Lib\asyncio\base_events.py", line 654, in run_until_complete
    return future.result()
           ^^^^^^^^^^^^^^^
  File "C:\Users\MyBook Z Series\AppData\Local\Packages\PythonSoftwareFoundation.Python.3.11_qbz5n2kfra8p0\LocalCache\local-packages\Python311\site-packages\nbclient\client.py", line 709, in async_execute
    await self.async_execute_cell(
  File "C:\Users\MyBook Z Series\AppData\Local\Packages\PythonSoftwareFoundation.Python.3.11_qbz5n2kfra8p0\LocalCache\local-packages\Python311\site-packages\nbclient\client.py", line 1062, in async_execute_cell
    await self._check_raise_for_error(cell, cell_index, exec_reply)
  File "C:\Users\MyBook Z Series\AppData\Local\Packages\PythonSoftwareFoundation.Python.3.11_qbz5n2kfra8p0\LocalCache\local-packages\Python311\site-packages\nbclient\client.py", line 918, in _check_raise_for_error
    raise CellExecutionError.from_cell_and_msg(cell, exec_reply_content)
nbclient.exceptions.CellExecutionError: An error occurred while executing the following cell:
------------------
# Mengkoneksi database dengan python
# for mysql
timeout = 10
connection = pymysql.connect(
    charset="utf8mb4",
    connect_timeout=timeout,
    cursorclass=pymysql.cursors.DictCursor,
    db="defaultdb",
    host="mysql-726cd75-mysqlpendata-11.h.aivencloud.com",
    password="AVNS_LHA80D-LNsKI6wncjfc",
    read_timeout=timeout,
    port=20734,
    user="avnadmin",
    write_timeout=timeout,
)
mysql_engine = create_engine("mysql+pymysql://avnadmin:AVNS_LHA80D-LNsKI6wncjfc@mysql-726cd75-mysqlpendata-11.h.aivencloud.com:20734/defaultdb")



# for postgre
def main():
    conn = psycopg2.connect('postgres://avnadmin:AVNS__Y6I8K0T7rSnwnRgE1U@pg-3266d3cf-postgresqlpendata-11.h.aivencloud.com:20817/defaultdb?sslmode=require')

    query_sql = 'SELECT VERSION()'

    cur = conn.cursor()
    cur.execute(query_sql)

    version = cur.fetchone()[0]
    print(version)

if __name__ == "__main__":
    main()
postgres_engine = create_engine("postgresql+psycopg2://avnadmin:AVNS__Y6I8K0T7rSnwnRgE1U@pg-3266d3cf-postgresqlpendata-11.h.aivencloud.com:20817/defaultdb")



------------------


[1;31m---------------------------------------------------------------------------[0m
[1;31mOperationalError[0m                          Traceback (most recent call last)
Cell [1;32mIn[2], line 33[0m
[0;32m     30[0m     [38;5;28mprint[39m(version)
[0;32m     32[0m [38;5;28;01mif[39;00m [38;5;18m__name__[39m [38;5;241m==[39m [38;5;124m"[39m[38;5;124m__main__[39m[38;5;124m"[39m:
[1;32m---> 33[0m     [43mmain[49m[43m([49m[43m)[49m
[0;32m     34[0m postgres_engine [38;5;241m=[39m create_engine([38;5;124m"[39m[38;5;124mpostgresql+psycopg2://avnadmin:AVNS__Y6I8K0T7rSnwnRgE1U@pg-3266d3cf-postgresqlpendata-11.h.aivencloud.com:20817/defaultdb[39m[38;5;124m"[39m)

Cell [1;32mIn[2], line 22[0m, in [0;36mmain[1;34m()[0m
[0;32m     21[0m [38;5;28;01mdef[39;00m[38;5;250m [39m[38;5;21mmain[39m():
[1;32m---> 22[0m     conn [38;5;241m=[39m [43mpsycopg2[49m[38;5;241;43m.[39;49m[43mconnect[49m[43m([49m[38;5;124;43m'[39;49m[38;5;124;43mpostgres://avnadmin:AVNS__Y6I8K0T7rSnwnRgE1U@pg-3266d3cf-postgresqlpendata-11.h.aivencloud.com:20817/defaultdb?sslmode=require[39;49m[38;5;124;43m'[39;49m[43m)[49m
[0;32m     24[0m     query_sql [38;5;241m=[39m [38;5;124m'[39m[38;5;124mSELECT VERSION()[39m[38;5;124m'[39m
[0;32m     26[0m     cur [38;5;241m=[39m conn[38;5;241m.[39mcursor()

File [1;32m~\AppData\Local\Packages\PythonSoftwareFoundation.Python.3.11_qbz5n2kfra8p0\LocalCache\local-packages\Python311\site-packages\psycopg2\__init__.py:122[0m, in [0;36mconnect[1;34m(dsn, connection_factory, cursor_factory, **kwargs)[0m
[0;32m    119[0m     kwasync[[38;5;124m'[39m[38;5;124masync_[39m[38;5;124m'[39m] [38;5;241m=[39m kwargs[38;5;241m.[39mpop([38;5;124m'[39m[38;5;124masync_[39m[38;5;124m'[39m)
[0;32m    121[0m dsn [38;5;241m=[39m _ext[38;5;241m.[39mmake_dsn(dsn, [38;5;241m*[39m[38;5;241m*[39mkwargs)
[1;32m--> 122[0m conn [38;5;241m=[39m [43m_connect[49m[43m([49m[43mdsn[49m[43m,[49m[43m [49m[43mconnection_factory[49m[38;5;241;43m=[39;49m[43mconnection_factory[49m[43m,[49m[43m [49m[38;5;241;43m*[39;49m[38;5;241;43m*[39;49m[43mkwasync[49m[43m)[49m
[0;32m    123[0m [38;5;28;01mif[39;00m cursor_factory [38;5;129;01mis[39;00m [38;5;129;01mnot[39;00m [38;5;28;01mNone[39;00m:
[0;32m    124[0m     conn[38;5;241m.[39mcursor_factory [38;5;241m=[39m cursor_factory

[1;31mOperationalError[0m: connection to server at "pg-3266d3cf-postgresqlpendata-11.h.aivencloud.com" (36.86.63.182), port 20817 failed: Connection timed out (0x0000274C/10060)
	Is the server running on that host and accepting TCP/IP connections?


